Workbook

Sheet Dashboard
A1: CASH FLOW STATEMENT – EXECUTIVE DASHBOARD
A2: All figures in Turkish Lira (₺) unless stated. Every number on this page is a formula driven by the four register tabs.
B4: REPORT SETTINGS (blue = input)
B5: Company / Entity | C5: Company Name Ltd. – Türkiye
B6: Report Period | C6: August 2026
B7: Prepared By | C7: Finance Department | F7: FX RATES TO ₺ (blue = input) | I7: LEGEND
B8: Report Date (as at) | C8: 46265 | F8: Currency | G8: 1 unit = ₺ | I8: Blue text / yellow fill | J8: User input
B9: WEEK START DATES | C9: Start date | F9: GBP | G9: 55.2 | I9: Black text | J9: Formula – do not edit
B10: Week 1 | C10: 46237 | F10: EUR | G10: 47.8 | I10: Green text | J10: Link to another tab
B11: Week 2 | C11: =C10+7 -> 46244 | F11: USD | G11: 41.3 | I11: Red status | J11: Overdue – action required
B12: Week 3 | C12: =C11+7 -> 46251 | F12: TRY | G12: 1 | I12: Green status | J12: Collected / Paid / Settled
B13: Week 4 | C13: =C12+7 -> 46258 | I13: Sample rows in each tab are examples – overwrite them with live data.
B14: Week 5 | C14: =C13+7 -> 46265
B16: KEY LIQUIDITY INDICATORS (₺)
B17: Bank & Cash Balance | C17: Receivables Outstanding | F17: Payables Outstanding | G17: UK HQ Outstanding | H17: Total Liabilities | I17: Net Cash Position | J17: Liquidity Ratio
B18: ='Bank Balances'!H25 -> 2475500 | C18: =Receivables!M47 -> 305000 | F18: =Payables!N47 -> 34300 | G18: ='UK HQ Invoices'!P47 -> 1103480 | H18: =F18+G18 -> 1137780 | I18: =B18+C18-H18 -> 1642720 | J18: =IF(H18=0,"n/a",(B18+C18)/H18) -> 2.4437941
B20: 5-WEEK CASH FLOW PROJECTION (₺)
B21: Line item | F21: =C10 -> 46237 | G21: =C11 -> 46244 | H21: =C12 -> 46251 | I21: =C13 -> 46258 | J21: =C14 -> 46265 | K21: Total
B22: Week | F22: Week 1 | G22: Week 2 | H22: Week 3 | I22: Week 4 | J22: Week 5
B23: Opening balance | F23: ='Bank Balances'!H25 -> 2475500 | G23: =F28 -> 2450500 | H23: =G28 -> 2510500 | I23: =H28 -> 2573000 | J23: =I28 -> 2253000 | K23: =F23 -> 2475500
B24: (+) Customer collections | F24: =Receivables!G47 -> 60000 | G24: =Receivables!H47 -> 60000 | H24: =Receivables!I47 -> 92500 | I24: =Receivables!J47 -> 0 | J24: =Receivables!K47 -> 0 | K24: =SUM(F24:J24) -> 212500
B25: (–) Supplier & operating payments | F25: =-Payables!H47 -> -85000 | G25: =-Payables!I47 -> 0 | H25: =-Payables!J47 -> -30000 | I25: =-Payables!K47 -> -320000 | J25: =-Payables!L47 -> 0 | K25: =SUM(F25:J25) -> -435000
B26: (–) UK HQ settlements | F26: =-'UK HQ Invoices'!J47 -> 0 | G26: =-'UK HQ Invoices'!K47 -> 0 | H26: =-'UK HQ Invoices'!L47 -> 0 | I26: =-'UK HQ Invoices'!M47 -> 0 | J26: =-'UK HQ Invoices'!N47 -> 0 | K26: =SUM(F26:J26) -> 0
B27: Net cash flow | F27: =SUM(F24:F26) -> -25000 | G27: =SUM(G24:G26) -> 60000 | H27: =SUM(H24:H26) -> 62500 | I27: =SUM(I24:I26) -> -320000 | J27: =SUM(J24:J26) -> 0 | K27: =SUM(F27:J27) -> -222500
B28: Closing balance | F28: =F23+F27 -> 2450500 | G28: =G23+G27 -> 2510500 | H28: =H23+H27 -> 2573000 | I28: =I23+I27 -> 2253000 | J28: =J23+J27 -> 2253000 | K28: =J28 -> 2253000
B29: Control: Closing week 5 = Bank & Cash + total net cash flow (must be 0) | K29: =J28-(B18+K27) -> 0
B30: Note: the projection assumes only the collections / payments scheduled in the week columns of each tab occur. Unscheduled balances remain outstanding.
B32: POSITION ANALYSIS
B33: Receivables by status | C33: Outstanding (₺) | F33: Payables by category | G33: Outstanding (₺) | I33: UK HQ aging | J33: Outstanding (₺) | K33: % of total
B34: Open | C34: =SUMIF(Receivables!P7:P46,"Open",Receivables!M7:M46) -> 240000 | F34: Payroll | G34: =SUMIF(Payables!C7:C46,F34,Payables!N7:N46) -> 0 | I34: Not due | J34: =SUMIF('UK HQ Invoices'!R7:R46,I34,'UK HQ Invoices'!P7:P46) -> 0 | K34: =IF($J$39=0,"",J34/$J$39) -> 0
B35: Overdue | C35: =SUMIF(Receivables!P7:P46,"Overdue",Receivables!M7:M46) -> 65000 | F35: Rent & Utilities | G35: =SUMIF(Payables!C7:C46,F35,Payables!N7:N46) -> 0 | I35: 1-30 days | J35: =SUMIF('UK HQ Invoices'!R7:R46,I35,'UK HQ Invoices'!P7:P46) -> 181640 | K35: =IF($J$39=0,"",J35/$J$39) -> 0.16460652
B36: Collected | C36: =SUMIF(Receivables!P7:P46,"Collected",Receivables!L7:L46) -> 92500 | F36: Suppliers / COGS | G36: =SUMIF(Payables!C7:C46,F36,Payables!N7:N46) -> 34300 | I36: 31-60 days | J36: =SUMIF('UK HQ Invoices'!R7:R46,I36,'UK HQ Invoices'!P7:P46) -> 231840 | K36: =IF($J$39=0,"",J36/$J$39) -> 0.21009896
B37: Invoiced total | C37: =Receivables!F47 -> 517500 | F37: Taxes & Social Security | G37: =SUMIF(Payables!C7:C46,F37,Payables!N7:N46) -> 0 | I37: 61-90 days | J37: =SUMIF('UK HQ Invoices'!R7:R46,I37,'UK HQ Invoices'!P7:P46) -> 690000 | K37: =IF($J$39=0,"",J37/$J$39) -> 0.62529452
B38: Collection rate | C38: =Receivables!N47 -> 0.41062802 | F38: Marketing | G38: =SUMIF(Payables!C7:C46,F38,Payables!N7:N46) -> 0 | I38: 90+ days | J38: =SUMIF('UK HQ Invoices'!R7:R46,I38,'UK HQ Invoices'!P7:P46) -> 0 | K38: =IF($J$39=0,"",J38/$J$39) -> 0
B39: Overdue invoices (count) | C39: =Receivables!O47 -> 1 | F39: IT & Software | G39: =SUMIF(Payables!C7:C46,F39,Payables!N7:N46) -> 0 | I39: Total outstanding | J39: =SUM(J34:J38) -> 1103480 | K39: =IF(J39=0,"",1) -> 1
F40: Professional Fees | G40: =SUMIF(Payables!C7:C46,F40,Payables!N7:N46) -> 0 | I40: Overdue HQ invoices (count) | J40: ='UK HQ Invoices'!Q47 -> 3
B41: Bank & cash by currency | C41: Equivalent (₺) | F41: Loan / Finance | G41: =SUMIF(Payables!C7:C46,F41,Payables!N7:N46) -> 0
B42: TRY | C42: =SUMIF('Bank Balances'!E5:E24,B42,'Bank Balances'!H5:H24) -> 1758500 | F42: Other | G42: =SUMIF(Payables!C7:C46,F42,Payables!N7:N46) -> 0
B43: GBP | C43: =SUMIF('Bank Balances'!E5:E24,B43,'Bank Balances'!H5:H24) -> 0 | F43: Total outstanding | G43: =SUM(G34:G42) -> 34300
B44: EUR | C44: =SUMIF('Bank Balances'!E5:E24,B44,'Bank Balances'!H5:H24) -> 717000 | F44: Check vs Payables tab (must be 0) | G44: =G43-Payables!N47 -> 0
...

Sheet Receivables
A1: ACCOUNTS RECEIVABLE – CUSTOMER COLLECTIONS
A2: Amounts in Turkish Lira (₺). Blue cells are inputs; black cells are formulas – do not overwrite.
G4: COLLECTIONS RECEIVED BY WEEK (₺) – week start dates below
A5: No | B5: Customer | C5: Invoice No | D5: Invoice Date | E5: Due Date | F5: Invoice Amount (₺) | G5: Week 1 | H5: Week 2 | I5: Week 3 | J5: Week 4 | K5: Week 5 | L5: Total Collected (₺) | M5: Remaining (₺) | N5: Collected % | O5: Days Overdue | P5: Status | Q5: Notes
B6: Week starting → | G6: =Dashboard!$C$10 -> 46237 | H6: =Dashboard!$C$11 -> 46244 | I6: =Dashboard!$C$12 -> 46251 | J6: =Dashboard!$C$13 -> 46258 | K6: =Dashboard!$C$14 -> 46265
A7: =IF(B7="","",ROW()-6) -> 1 | B7: Anadolu Retail A.Ş. | C7: INV-2026-081 | D7: 46218 | E7: 46248 | F7: 185000 | G7: 60000 | H7: 60000 | L7: =IF(B7="","",SUM(G7:K7)) -> 120000 | M7: =IF(B7="","",F7-L7) -> 65000 | N7: =IF(OR(B7="",F7=0),"",L7/F7) -> 0.64864865 | O7: =IF(OR(B7="",E7="",M7<=0),"",MAX(0,Dashboard!$C$8-E7)) -> 17 | P7: =IF(B7="","",IF(M7<=0,"Collected",IF(AND(O7<>"",O7>0),"Overdue","Open"))) -> Overdue | Q7: Sample row – replace with live data
A8: =IF(B8="","",ROW()-6) -> 2 | B8: Marmara Lojistik Ltd. | C8: INV-2026-084 | D8: 46231 | E8: 46261 | F8: 92500 | I8: 92500 | L8: =IF(B8="","",SUM(G8:K8)) -> 92500 | M8: =IF(B8="","",F8-L8) -> 0 | N8: =IF(OR(B8="",F8=0),"",L8/F8) -> 1 | O8: =IF(OR(B8="",E8="",M8<=0),"",MAX(0,Dashboard!$C$8-E8)) | P8: =IF(B8="","",IF(M8<=0,"Collected",IF(AND(O8<>"",O8>0),"Overdue","Open"))) -> Collected | Q8: Sample row – replace with live data
A9: =IF(B9="","",ROW()-6) -> 3 | B9: Ege Gıda San. Tic. | C9: INV-2026-087 | D9: 46237 | E9: 46267 | F9: 240000 | L9: =IF(B9="","",SUM(G9:K9)) -> 0 | M9: =IF(B9="","",F9-L9) -> 240000 | N9: =IF(OR(B9="",F9=0),"",L9/F9) -> 0 | O9: =IF(OR(B9="",E9="",M9<=0),"",MAX(0,Dashboard!$C$8-E9)) -> 0 | P9: =IF(B9="","",IF(M9<=0,"Collected",IF(AND(O9<>"",O9>0),"Overdue","Open"))) -> Open | Q9: Sample row – replace with live data
A10: =IF(B10="","",ROW()-6) | L10: =IF(B10="","",SUM(G10:K10)) | M10: =IF(B10="","",F10-L10) | N10: =IF(OR(B10="",F10=0),"",L10/F10) | O10: =IF(OR(B10="",E10="",M10<=0),"",MAX(0,Dashboard!$C$8-E10)) | P10: =IF(B10="","",IF(M10<=0,"Collected",IF(AND(O10<>"",O10>0),"Overdue","Open")))
A11: =IF(B11="","",ROW()-6) | L11: =IF(B11="","",SUM(G11:K11)) | M11: =IF(B11="","",F11-L11) | N11: =IF(OR(B11="",F11=0),"",L11/F11) | O11: =IF(OR(B11="",E11="",M11<=0),"",MAX(0,Dashboard!$C$8-E11)) | P11: =IF(B11="","",IF(M11<=0,"Collected",IF(AND(O11<>"",O11>0),"Overdue","Open")))
A12: =IF(B12="","",ROW()-6) | L12: =IF(B12="","",SUM(G12:K12)) | M12: =IF(B12="","",F12-L12) | N12: =IF(OR(B12="",F12=0),"",L12/F12) | O12: =IF(OR(B12="",E12="",M12<=0),"",MAX(0,Dashboard!$C$8-E12)) | P12: =IF(B12="","",IF(M12<=0,"Collected",IF(AND(O12<>"",O12>0),"Overdue","Open")))
A13: =IF(B13="","",ROW()-6) | L13: =IF(B13="","",SUM(G13:K13)) | M13: =IF(B13="","",F13-L13) | N13: =IF(OR(B13="",F13=0),"",L13/F13) | O13: =IF(OR(B13="",E13="",M13<=0),"",MAX(0,Dashboard!$C$8-E13)) | P13: =IF(B13="","",IF(M13<=0,"Collected",IF(AND(O13<>"",O13>0),"Overdue","Open")))
A14: =IF(B14="","",ROW()-6) | L14: =IF(B14="","",SUM(G14:K14)) | M14: =IF(B14="","",F14-L14) | N14: =IF(OR(B14="",F14=0),"",L14/F14) | O14: =IF(OR(B14="",E14="",M14<=0),"",MAX(0,Dashboard!$C$8-E14)) | P14: =IF(B14="","",IF(M14<=0,"Collected",IF(AND(O14<>"",O14>0),"Overdue","Open")))
A15: =IF(B15="","",ROW()-6) | L15: =IF(B15="","",SUM(G15:K15)) | M15: =IF(B15="","",F15-L15) | N15: =IF(OR(B15="",F15=0),"",L15/F15) | O15: =IF(OR(B15="",E15="",M15<=0),"",MAX(0,Dashboard!$C$8-E15)) | P15: =IF(B15="","",IF(M15<=0,"Collected",IF(AND(O15<>"",O15>0),"Overdue","Open")))
A16: =IF(B16="","",ROW()-6) | L16: =IF(B16="","",SUM(G16:K16)) | M16: =IF(B16="","",F16-L16) | N16: =IF(OR(B16="",F16=0),"",L16/F16) | O16: =IF(OR(B16="",E16="",M16<=0),"",MAX(0,Dashboard!$C$8-E16)) | P16: =IF(B16="","",IF(M16<=0,"Collected",IF(AND(O16<>"",O16>0),"Overdue","Open")))
A17: =IF(B17="","",ROW()-6) | L17: =IF(B17="","",SUM(G17:K17)) | M17: =IF(B17="","",F17-L17) | N17: =IF(OR(B17="",F17=0),"",L17/F17) | O17: =IF(OR(B17="",E17="",M17<=0),"",MAX(0,Dashboard!$C$8-E17)) | P17: =IF(B17="","",IF(M17<=0,"Collected",IF(AND(O17<>"",O17>0),"Overdue","Open")))
A18: =IF(B18="","",ROW()-6) | L18: =IF(B18="","",SUM(G18:K18)) | M18: =IF(B18="","",F18-L18) | N18: =IF(OR(B18="",F18=0),"",L18/F18) | O18: =IF(OR(B18="",E18="",M18<=0),"",MAX(0,Dashboard!$C$8-E18)) | P18: =IF(B18="","",IF(M18<=0,"Collected",IF(AND(O18<>"",O18>0),"Overdue","Open")))
A19: =IF(B19="","",ROW()-6) | L19: =IF(B19="","",SUM(G19:K19)) | M19: =IF(B19="","",F19-L19) | N19: =IF(OR(B19="",F19=0),"",L19/F19) | O19: =IF(OR(B19="",E19="",M19<=0),"",MAX(0,Dashboard!$C$8-E19)) | P19: =IF(B19="","",IF(M19<=0,"Collected",IF(AND(O19<>"",O19>0),"Overdue","Open")))
A20: =IF(B20="","",ROW()-6) | L20: =IF(B20="","",SUM(G20:K20)) | M20: =IF(B20="","",F20-L20) | N20: =IF(OR(B20="",F20=0),"",L20/F20) | O20: =IF(OR(B20="",E20="",M20<=0),"",MAX(0,Dashboard!$C$8-E20)) | P20: =IF(B20="","",IF(M20<=0,"Collected",IF(AND(O20<>"",O20>0),"Overdue","Open")))
A21: =IF(B21="","",ROW()-6) | L21: =IF(B21="","",SUM(G21:K21)) | M21: =IF(B21="","",F21-L21) | N21: =IF(OR(B21="",F21=0),"",L21/F21) | O21: =IF(OR(B21="",E21="",M21<=0),"",MAX(0,Dashboard!$C$8-E21)) | P21: =IF(B21="","",IF(M21<=0,"Collected",IF(AND(O21<>"",O21>0),"Overdue","Open")))
... A46: =IF(B46="","",ROW()-6) | L46: =IF(B46="","",SUM(G46:K46)) | M46: =IF(B46="","",F46-L46) | N46: =IF(OR(B46="",F46=0),"",L46/F46) | O46: =IF(OR(B46="",E46="",M46<=0),"",MAX(0,Dashboard!$C$8-E46)) | P46: =IF(B46="","",IF(M46<=0,"Collected",IF(AND(O46<>"",O46>0),"Overdue","Open")))
B47: TOTAL | F47: =SUM(F7:F46) -> 517500 | G47: =SUM(G7:G46) -> 60000 | H47: =SUM(H7:H46) -> 60000 | I47: =SUM(I7:I46) -> 92500 | J47: =SUM(J7:J46) -> 0 | K47: =SUM(K7:K46) -> 0 | L47: =SUM(L7:L46) -> 212500 | M47: =SUM(M7:M46) -> 305000 | N47: =IF(F47=0,"",L47/F47) -> 0.41062802 | O47: =COUNTIF(P7:P46,"Overdue") -> 1 | P47: overdue
B49: Control: Invoice total – Collected – Remaining (must be 0) | F49: =F47-L47-M47 -> 0

Sheet Payables
A1: ACCOUNTS PAYABLE – SCHEDULED PAYMENTS
A2: Amounts in Turkish Lira (₺). Blue cells are inputs; black cells are formulas – do not overwrite.
H4: PAYMENTS PLANNED / MADE BY WEEK (₺) – week start dates below
A5: No | B5: Supplier / Payee | C5: Category | D5: Invoice No | E5: Invoice Date | F5: Due Date | G5: Invoice Amount (₺) | H5: Week 1 | I5: Week 2 | J5: Week 3 | K5: Week 4 | L5: Week 5 | M5: Total Paid (₺) | N5: Remaining (₺) | O5: Paid % | P5: Days Overdue | Q5: Status | R5: Notes
B6: Week starting → | H6: =Dashboard!$C$10 -> 46237 | I6: =Dashboard!$C$11 -> 46244 | J6: =Dashboard!$C$12 -> 46251 | K6: =Dashboard!$C$13 -> 46258 | L6: =Dashboard!$C$14 -> 46265
A7: =IF(B7="","",ROW()-6) -> 1 | B7: Staff Payroll – August | C7: Payroll | D7: PAY-08-2026 | E7: 46259 | F7: 46265 | G7: 320000 | K7: 320000 | M7: =IF(B7="","",SUM(H7:L7)) -> 320000 | N7: =IF(B7="","",G7-M7) -> 0 | O7: =IF(OR(B7="",G7=0),"",M7/G7) -> 1 | P7: =IF(OR(B7="",F7="",N7<=0),"",MAX(0,Dashboard!$C$8-F7)) | Q7: =IF(B7="","",IF(N7<=0,"Paid",IF(AND(P7<>"",P7>0),"Overdue","Scheduled"))) -> Paid | R7: Sample row – replace with live data
A8: =IF(B8="","",ROW()-6) -> 2 | B8: İstanbul Office Rent | C8: Rent & Utilities | D8: RNT-2026-08 | E8: 46235 | F8: 46239 | G8: 85000 | H8: 85000 | M8: =IF(B8="","",SUM(H8:L8)) -> 85000 | N8: =IF(B8="","",G8-M8) -> 0 | O8: =IF(OR(B8="",G8=0),"",M8/G8) -> 1 | P8: =IF(OR(B8="",F8="",N8<=0),"",MAX(0,Dashboard!$C$8-F8)) | Q8: =IF(B8="","",IF(N8<=0,"Paid",IF(AND(P8<>"",P8>0),"Overdue","Scheduled"))) -> Paid | R8: Sample row – replace with live data
A9: =IF(B9="","",ROW()-6) -> 3 | B9: Karadeniz Ambalaj Ltd. | C9: Suppliers / COGS | D9: SUP-4471 | E9: 46223 | F9: 46253 | G9: 64300 | J9: 30000 | M9: =IF(B9="","",SUM(H9:L9)) -> 30000 | N9: =IF(B9="","",G9-M9) -> 34300 | O9: =IF(OR(B9="",G9=0),"",M9/G9) -> 0.46656299 | P9: =IF(OR(B9="",F9="",N9<=0),"",MAX(0,Dashboard!$C$8-F9)) -> 12 | Q9: =IF(B9="","",IF(N9<=0,"Paid",IF(AND(P9<>"",P9>0),"Overdue","Scheduled"))) -> Overdue | R9: Sample row – replace with live data
A10: =IF(B10="","",ROW()-6) | M10: =IF(B10="","",SUM(H10:L10)) | N10: =IF(B10="","",G10-M10) | O10: =IF(OR(B10="",G10=0),"",M10/G10) | P10: =IF(OR(B10="",F10="",N10<=0),"",MAX(0,Dashboard!$C$8-F10)) | Q10: =IF(B10="","",IF(N10<=0,"Paid",IF(AND(P10<>"",P10>0),"Overdue","Scheduled")))
A11: =IF(B11="","",ROW()-6) | M11: =IF(B11="","",SUM(H11:L11)) | N11: =IF(B11="","",G11-M11) | O11: =IF(OR(B11="",G11=0),"",M11/G11) | P11: =IF(OR(B11="",F11="",N11<=0),"",MAX(0,Dashboard!$C$8-F11)) | Q11: =IF(B11="","",IF(N11<=0,"Paid",IF(AND(P11<>"",P11>0),"Overdue","Scheduled")))
A12: =IF(B12="","",ROW()-6) | M12: =IF(B12="","",SUM(H12:L12)) | N12: =IF(B12="","",G12-M12) | O12: =IF(OR(B12="",G12=0),"",M12/G12) | P12: =IF(OR(B12="",F12="",N12<=0),"",MAX(0,Dashboard!$C$8-F12)) | Q12: =IF(B12="","",IF(N12<=0,"Paid",IF(AND(P12<>"",P12>0),"Overdue","Scheduled")))
A13: =IF(B13="","",ROW()-6) | M13: =IF(B13="","",SUM(H13:L13)) | N13: =IF(B13="","",G13-M13) | O13: =IF(OR(B13="",G13=0),"",M13/G13) | P13: =IF(OR(B13="",F13="",N13<=0),"",MAX(0,Dashboard!$C$8-F13)) | Q13: =IF(B13="","",IF(N13<=0,"Paid",IF(AND(P13<>"",P13>0),"Overdue","Scheduled")))
A14: =IF(B14="","",ROW()-6) | M14: =IF(B14="","",SUM(H14:L14)) | N14: =IF(B14="","",G14-M14) | O14: =IF(OR(B14="",G14=0),"",M14/G14) | P14: =IF(OR(B14="",F14="",N14<=0),"",MAX(0,Dashboard!$C$8-F14)) | Q14: =IF(B14="","",IF(N14<=0,"Paid",IF(AND(P14<>"",P14>0),"Overdue","Scheduled")))
A15: =IF(B15="","",ROW()-6) | M15: =IF(B15="","",SUM(H15:L15)) | N15: =IF(B15="","",G15-M15) | O15: =IF(OR(B15="",G15=0),"",M15/G15) | P15: =IF(OR(B15="",F15="",N15<=0),"",MAX(0,Dashboard!$C$8-F15)) | Q15: =IF(B15="","",IF(N15<=0,"Paid",IF(AND(P15<>"",P15>0),"Overdue","Scheduled")))
A16: =IF(B16="","",ROW()-6) | M16: =IF(B16="","",SUM(H16:L16)) | N16: =IF(B16="","",G16-M16) | O16: =IF(OR(B16="",G16=0),"",M16/G16) | P16: =IF(OR(B16="",F16="",N16<=0),"",MAX(0,Dashboard!$C$8-F16)) | Q16: =IF(B16="","",IF(N16<=0,"Paid",IF(AND(P16<>"",P16>0),"Overdue","Scheduled")))
A17: =IF(B17="","",ROW()-6) | M17: =IF(B17="","",SUM(H17:L17)) | N17: =IF(B17="","",G17-M17) | O17: =IF(OR(B17="",G17=0),"",M17/G17) | P17: =IF(OR(B17="",F17="",N17<=0),"",MAX(0,Dashboard!$C$8-F17)) | Q17: =IF(B17="","",IF(N17<=0,"Paid",IF(AND(P17<>"",P17>0),"Overdue","Scheduled")))
A18: =IF(B18="","",ROW()-6) | M18: =IF(B18="","",SUM(H18:L18)) | N18: =IF(B18="","",G18-M18) | O18: =IF(OR(B18="",G18=0),"",M18/G18) | P18: =IF(OR(B18="",F18="",N18<=0),"",MAX(0,Dashboard!$C$8-F18)) | Q18: =IF(B18="","",IF(N18<=0,"Paid",IF(AND(P18<>"",P18>0),"Overdue","Scheduled")))
A19: =IF(B19="","",ROW()-6) | M19: =IF(B19="","",SUM(H19:L19)) | N19: =IF(B19="","",G19-M19) | O19: =IF(OR(B19="",G19=0),"",M19/G19) | P19: =IF(OR(B19="",F19="",N19<=0),"",MAX(0,Dashboard!$C$8-F19)) | Q19: =IF(B19="","",IF(N19<=0,"Paid",IF(AND(P19<>"",P19>0),"Overdue","Scheduled")))
A20: =IF(B20="","",ROW()-6) | M20: =IF(B20="","",SUM(H20:L20)) | N20: =IF(B20="","",G20-M20) | O20: =IF(OR(B20="",G20=0),"",M20/G20) | P20: =IF(OR(B20="",F20="",N20<=0),"",MAX(0,Dashboard!$C$8-F20)) | Q20: =IF(B20="","",IF(N20<=0,"Paid",IF(AND(P20<>"",P20>0),"Overdue","Scheduled")))
A21: =IF(B21="","",ROW()-6) | M21: =IF(B21="","",SUM(H21:L21)) | N21: =IF(B21="","",G21-M21) | O21: =IF(OR(B21="",G21=0),"",M21/G21) | P21: =IF(OR(B21="",F21="",N21<=0),"",MAX(0,Dashboard!$C$8-F21)) | Q21: =IF(B21="","",IF(N21<=0,"Paid",IF(AND(P21<>"",P21>0),"Overdue","Scheduled")))
... A46: =IF(B46="","",ROW()-6) | M46: =IF(B46="","",SUM(H46:L46)) | N46: =IF(B46="","",G46-M46) | O46: =IF(OR(B46="",G46=0),"",M46/G46) | P46: =IF(OR(B46="",F46="",N46<=0),"",MAX(0,Dashboard!$C$8-F46)) | Q46: =IF(B46="","",IF(N46<=0,"Paid",IF(AND(P46<>"",P46>0),"Overdue","Scheduled")))
B47: TOTAL | G47: =SUM(G7:G46) -> 469300 | H47: =SUM(H7:H46) -> 85000 | I47: =SUM(I7:I46) -> 0 | J47: =SUM(J7:J46) -> 30000 | K47: =SUM(K7:K46) -> 320000 | L47: =SUM(L7:L46) -> 0 | M47: =SUM(M7:M46) -> 435000 | N47: =SUM(N7:N46) -> 34300 | O47: =IF(G47=0,"",M47/G47) -> 0.92691242 | P47: =COUNTIF(Q7:Q46,"Overdue") -> 1 | Q47: overdue
B49: Control: Invoice total – Paid – Remaining (must be 0) | G49: =G47-M47-N47 -> 0

Sheet UK HQ Invoices
A1: UK HQ – OUTSTANDING INTERCOMPANY INVOICES
A2: Invoices received from UK Head Office not yet settled. Foreign currency amounts convert to ₺ using the FX rates on the Dashboard.
J4: SETTLEMENTS PLANNED / MADE BY WEEK (₺) – week start dates below
A5: No | B5: HQ Invoice No | C5: Invoice Date | D5: Due Date | E5: Description / Service | F5: Currency | G5: Invoice Amount (FCY) | H5: FX Rate (to ₺) | I5: Invoice Amount (₺) | J5: Week 1 | K5: Week 2 | L5: Week 3 | M5: Week 4 | N5: Week 5 | O5: Total Paid (₺) | P5: Remaining (₺) | Q5: Days Overdue | R5: Aging Bucket | S5: Status | T5: Notes
E6: Week starting → | J6: =Dashboard!$C$10 -> 46237 | K6: =Dashboard!$C$11 -> 46244 | L6: =Dashboard!$C$12 -> 46251 | M6: =Dashboard!$C$13 -> 46258 | N6: =Dashboard!$C$14 -> 46265
A7: =IF(B7="","",ROW()-6) -> 1 | B7: UKHQ-2026-0412 | C7: 46172 | D7: 46202 | E7: Management fee – Q2 2026 | F7: GBP | G7: 12500 | H7: =IF(B7="","",IFERROR(INDEX(Dashboard!$G$9:$G$12,MATCH(F7,Dashboard!$F$9:$F$12,0)),1)) -> 55.2 | I7: =IF(B7="","",G7*H7) -> 690000 | O7: =IF(B7="","",SUM(J7:N7)) -> 0 | P7: =IF(B7="","",I7-O7) -> 690000 | Q7: =IF(OR(B7="",D7="",P7<=0),"",MAX(0,Dashboard!$C$8-D7)) -> 63 | R7: =IF(OR(B7="",P7<=0),"",IF(Q7=0,"Not due",IF(Q7<=30,"1-30 days",IF(Q7<=60,"31-60 days",IF(Q7<=90,"61-90 days","90+ days"))))) -> 61-90 days | S7: =IF(B7="","",IF(P7<=0,"Settled",IF(AND(Q7<>"",Q7>0),"Overdue","Open"))) -> Overdue | T7: Sample row – replace with live data
A8: =IF(B8="","",ROW()-6) -> 2 | B8: UKHQ-2026-0498 | C8: 46203 | D8: 46233 | E8: Software licences recharge | F8: GBP | G8: 4200 | H8: =IF(B8="","",IFERROR(INDEX(Dashboard!$G$9:$G$12,MATCH(F8,Dashboard!$F$9:$F$12,0)),1)) -> 55.2 | I8: =IF(B8="","",G8*H8) -> 231840 | O8: =IF(B8="","",SUM(J8:N8)) -> 0 | P8: =IF(B8="","",I8-O8) -> 231840 | Q8: =IF(OR(B8="",D8="",P8<=0),"",MAX(0,Dashboard!$C$8-D8)) -> 32 | R8: =IF(OR(B8="",P8<=0),"",IF(Q8=0,"Not due",IF(Q8<=30,"1-30 days",IF(Q8<=60,"31-60 days",IF(Q8<=90,"61-90 days","90+ days"))))) -> 31-60 days | S8: =IF(B8="","",IF(P8<=0,"Settled",IF(AND(Q8<>"",Q8>0),"Overdue","Open"))) -> Overdue | T8: Sample row – replace with live data
A9: =IF(B9="","",ROW()-6) -> 3 | B9: UKHQ-2026-0533 | C9: 46234 | D9: 46264 | E9: Group insurance recharge | F9: EUR | G9: 3800 | H9: =IF(B9="","",IFERROR(INDEX(Dashboard!$G$9:$G$12,MATCH(F9,Dashboard!$F$9:$F$12,0)),1)) -> 47.8 | I9: =IF(B9="","",G9*H9) -> 181640 | O9: =IF(B9="","",SUM(J9:N9)) -> 0 | P9: =IF(B9="","",I9-O9) -> 181640 | Q9: =IF(OR(B9="",D9="",P9<=0),"",MAX(0,Dashboard!$C$8-D9)) -> 1 | R9: =IF(OR(B9="",P9<=0),"",IF(Q9=0,"Not due",IF(Q9<=30,"1-30 days",IF(Q9<=60,"31-60 days",IF(Q9<=90,"61-90 days","90+ days"))))) -> 1-30 days | S9: =IF(B9="","",IF(P9<=0,"Settled",IF(AND(Q9<>"",Q9>0),"Overdue","Open"))) -> Overdue | T9: Sample row – replace with live data
A10: =IF(B10="","",ROW()-6) | H10: =IF(B10="","",IFERROR(INDEX(Dashboard!$G$9:$G$12,MATCH(F10,Dashboard!$F$9:$F$12,0)),1)) | I10: =IF(B10="","",G10*H10) | O10: =IF(B10="","",SUM(J10:N10)) | P10: =IF(B10="","",I10-O10) | Q10: =IF(OR(B10="",D10="",P10<=0),"",MAX(0,Dashboard!$C$8-D10)) | R10: =IF(OR(B10="",P10<=0),"",IF(Q10=0,"Not due",IF(Q10<=30,"1-30 days",IF(Q10<=60,"31-60 days",IF(Q10<=90,"61-90 days","90+ days"))))) | S10: =IF(B10="","",IF(P10<=0,"Settled",IF(AND(Q10<>"",Q10>0),"Overdue","Open")))
A11: =IF(B11="","",ROW()-6) | H11: =IF(B11="","",IFERROR(INDEX(Dashboard!$G$9:$G$12,MATCH(F11,Dashboard!$F$9:$F$12,0)),1)) | I11: =IF(B11="","",G11*H11) | O11: =IF(B11="","",SUM(J11:N11)) | P11: =IF(B11="","",I11-O11) | Q11: =IF(OR(B11="",D11="",P11<=0),"",MAX(0,Dashboard!$C$8-D11)) | R11: =IF(OR(B11="",P11<=0),"",IF(Q11=0,"Not due",IF(Q11<=30,"1-30 days",IF(Q11<=60,"31-60 days",IF(Q11<=90,"61-90 days","90+ days"))))) | S11: =IF(B11="","",IF(P11<=0,"Settled",IF(AND(Q11<>"",Q11>0),"Overdue","Open")))
A12: =IF(B12="","",ROW()-6) | H12: =IF(B12="","",IFERROR(INDEX(Dashboard!$G$9:$G$12,MATCH(F12,Dashboard!$F$9:$F$12,0)),1)) | I12: =IF(B12="","",G12*H12) | O12: =IF(B12="","",SUM(J12:N12)) | P12: =IF(B12="","",I12-O12) | Q12: =IF(OR(B12="",D12="",P12<=0),"",MAX(0,Dashboard!$C$8-D12)) | R12: =IF(OR(B12="",P12<=0),"",IF(Q12=0,"Not due",IF(Q12<=30,"1-30 days",IF(Q12<=60,"31-60 days",IF(Q12<=90,"61-90 days","90+ days"))))) | S12: =IF(B12="","",IF(P12<=0,"Settled",IF(AND(Q12<>"",Q12>0),"Overdue","Open")))
A13: =IF(B13="","",ROW()-6) | H13: =IF(B13="","",IFERROR(INDEX(Dashboard!$G$9:$G$12,MATCH(F13,Dashboard!$F$9:$F$12,0)),1)) | I13: =IF(B13="","",G13*H13) | O13: =IF(B13="","",SUM(J13:N13)) | P13: =IF(B13="","",I13-O13) | Q13: =IF(OR(B13="",D13="",P13<=0),"",MAX(0,Dashboard!$C$8-D13)) | R13: =IF(OR(B13="",P13<=0),"",IF(Q13=0,"Not due",IF(Q13<=30,"1-30 days",IF(Q13<=60,"31-60 days",IF(Q13<=90,"61-90 days","90+ days"))))) | S13: =IF(B13="","",IF(P13<=0,"Settled",IF(AND(Q13<>"",Q13>0),"Overdue","Open")))
A14: =IF(B14="","",ROW()-6) | H14: =IF(B14="","",IFERROR(INDEX(Dashboard!$G$9:$G$12,MATCH(F14,Dashboard!$F$9:$F$12,0)),1)) | I14: =IF(B14="","",G14*H14) | O14: =IF(B14="","",SUM(J14:N14)) | P14: =IF(B14="","",I14-O14) | Q14: =IF(OR(B14="",D14="",P14<=0),"",MAX(0,Dashboard!$C$8-D14)) | R14: =IF(OR(B14="",P14<=0),"",IF(Q14=0,"Not due",IF(Q14<=30,"1-30 days",IF(Q14<=60,"31-60 days",IF(Q14<=90,"61-90 days","90+ days"))))) | S14: =IF(B14="","",IF(P14<=0,"Settled",IF(AND(Q14<>"",Q14>0),"Overdue","Open")))
A15: =IF(B15="","",ROW()-6) | H15: =IF(B15="","",IFERROR(INDEX(Dashboard!$G$9:$G$12,MATCH(F15,Dashboard!$F$9:$F$12,0)),1)) | I15: =IF(B15="","",G15*H15) | O15: =IF(B15="","",SUM(J15:N15)) | P15: =IF(B15="","",I15-O15) | Q15: =IF(OR(B15="",D15="",P15<=0),"",MAX(0,Dashboard!$C$8-D15)) | R15: =IF(OR(B15="",P15<=0),"",IF(Q15=0,"Not due",IF(Q15<=30,"1-30 days",IF(Q15<=60,"31-60 days",IF(Q15<=90,"61-90 days","90+ days"))))) | S15: =IF(B15="","",IF(P15<=0,"Settled",IF(AND(Q15<>"",Q15>0),"Overdue","Open")))
A16: =IF(B16="","",ROW()-6) | H16: =IF(B16="","",IFERROR(INDEX(Dashboard!$G$9:$G$12,MATCH(F16,Dashboard!$F$9:$F$12,0)),1)) | I16: =IF(B16="","",G16*H16) | O16: =IF(B16="","",SUM(J16:N16)) | P16: =IF(B16="","",I16-O16) | Q16: =IF(OR(B16="",D16="",P16<=0),"",MAX(0,Dashboard!$C$8-D16)) | R16: =IF(OR(B16="",P16<=0),"",IF(Q16=0,"Not due",IF(Q16<=30,"1-30 days",IF(Q16<=60,"31-60 days",IF(Q16<=90,"61-90 days","90+ days"))))) | S16: =IF(B16="","",IF(P16<=0,"Settled",IF(AND(Q16<>"",Q16>0),"Overdue","Open")))
A17: =IF(B17="","",ROW()-6) | H17: =IF(B17="","",IFERROR(INDEX(Dashboard!$G$9:$G$12,MATCH(F17,Dashboard!$F$9:$F$12,0)),1)) | I17: =IF(B17="","",G17*H17) | O17: =IF(B17="","",SUM(J17:N17)) | P17: =IF(B17="","",I17-O17) | Q17: =IF(OR(B17="",D17="",P17<=0),"",MAX(0,Dashboard!$C$8-D17)) | R17: =IF(OR(B17="",P17<=0),"",IF(Q17=0,"Not due",IF(Q17<=30,"1-30 days",IF(Q17<=60,"31-60 days",IF(Q17<=90,"61-90 days","90+ days"))))) | S17: =IF(B17="","",IF(P17<=0,"Settled",IF(AND(Q17<>"",Q17>0),"Overdue","Open")))
A18: =IF(B18="","",ROW()-6) | H18: =IF(B18="","",IFERROR(INDEX(Dashboard!$G$9:$G$12,MATCH(F18,Dashboard!$F$9:$F$12,0)),1)) | I18: =IF(B18="","",G18*H18) | O18: =IF(B18="","",SUM(J18:N18)) | P18: =IF(B18="","",I18-O18) | Q18: =IF(OR(B18="",D18="",P18<=0),"",MAX(0,Dashboard!$C$8-D18)) | R18: =IF(OR(B18="",P18<=0),"",IF(Q18=0,"Not due",IF(Q18<=30,"1-30 days",IF(Q18<=60,"31-60 days",IF(Q18<=90,"61-90 days","90+ days"))))) | S18: =IF(B18="","",IF(P18<=0,"Settled",IF(AND(Q18<>"",Q18>0),"Overdue","Open")))
A19: =IF(B19="","",ROW()-6) | H19: =IF(B19="","",IFERROR(INDEX(Dashboard!$G$9:$G$12,MATCH(F19,Dashboard!$F$9:$F$12,0)),1)) | I19: =IF(B19="","",G19*H19) | O19: =IF(B19="","",SUM(J19:N19)) | P19: =IF(B19="","",I19-O19) | Q19: =IF(OR(B19="",D19="",P19<=0),"",MAX(0,Dashboard!$C$8-D19)) | R19: =IF(OR(B19="",P19<=0),"",IF(Q19=0,"Not due",IF(Q19<=30,"1-30 days",IF(Q19<=60,"31-60 days",IF(Q19<=90,"61-90 days","90+ days"))))) | S19: =IF(B19="","",IF(P19<=0,"Settled",IF(AND(Q19<>"",Q19>0),"Overdue","Open")))
A20: =IF(B20="","",ROW()-6) | H20: =IF(B20="","",IFERROR(INDEX(Dashboard!$G$9:$G$12,MATCH(F20,Dashboard!$F$9:$F$12,0)),1)) | I20: =IF(B20="","",G20*H20) | O20: =IF(B20="","",SUM(J20:N20)) | P20: =IF(B20="","",I20-O20) | Q20: =IF(OR(B20="",D20="",P20<=0),"",MAX(0,Dashboard!$C$8-D20)) | R20: =IF(OR(B20="",P20<=0),"",IF(Q20=0,"Not due",IF(Q20<=30,"1-30 days",IF(Q20<=60,"31-60 days",IF(Q20<=90,"61-90 days","90+ days"))))) | S20: =IF(B20="","",IF(P20<=0,"Settled",IF(AND(Q20<>"",Q20>0),"Overdue","Open")))
A21: =IF(B21="","",ROW()-6) | H21: =IF(B21="","",IFERROR(INDEX(Dashboard!$G$9:$G$12,MATCH(F21,Dashboard!$F$9:$F$12,0)),1)) | I21: =IF(B21="","",G21*H21) | O21: =IF(B21="","",SUM(J21:N21)) | P21: =IF(B21="","",I21-O21) | Q21: =IF(OR(B21="",D21="",P21<=0),"",MAX(0,Dashboard!$C$8-D21)) | R21: =IF(OR(B21="",P21<=0),"",IF(Q21=0,"Not due",IF(Q21<=30,"1-30 days",IF(Q21<=60,"31-60 days",IF(Q21<=90,"61-90 days","90+ days"))))) | S21: =IF(B21="","",IF(P21<=0,"Settled",IF(AND(Q21<>"",Q21>0),"Overdue","Open")))
... A46: =IF(B46="","",ROW()-6) | H46: =IF(B46="","",IFERROR(INDEX(Dashboard!$G$9:$G$12,MATCH(F46,Dashboard!$F$9:$F$12,0)),1)) | I46: =IF(B46="","",G46*H46) | O46: =IF(B46="","",SUM(J46:N46)) | P46: =IF(B46="","",I46-O46) | Q46: =IF(OR(B46="",D46="",P46<=0),"",MAX(0,Dashboard!$C$8-D46)) | R46: =IF(OR(B46="",P46<=0),"",IF(Q46=0,"Not due",IF(Q46<=30,"1-30 days",IF(Q46<=60,"31-60 days",IF(Q46<=90,"61-90 days","90+ days"))))) | S46: =IF(B46="","",IF(P46<=0,"Settled",IF(AND(Q46<>"",Q46>0),"Overdue","Open")))
B47: TOTAL | I47: =SUM(I7:I46) -> 1103480 | J47: =SUM(J7:J46) -> 0 | K47: =SUM(K7:K46) -> 0 | L47: =SUM(L7:L46) -> 0 | M47: =SUM(M7:M46) -> 0 | N47: =SUM(N7:N46) -> 0 | O47: =SUM(O7:O46) -> 0 | P47: =SUM(P7:P46) -> 1103480 | Q47: =COUNTIF(S7:S46,"Overdue") -> 3 | S47: overdue
E49: Outstanding by currency (FCY)
E50: GBP | F50: =SUMIF(F7:F46,E50,G7:G46)-SUMPRODUCT((F7:F46=E50)*(O7:O46<>"")*IFERROR(O7:O46/H7:H46,0)) -> 16700
E51: EUR | F51: =SUMIF(F7:F46,E51,G7:G46)-SUMPRODUCT((F7:F46=E51)*(O7:O46<>"")*IFERROR(O7:O46/H7:H46,0)) -> 3800
E52: USD | F52: =SUMIF(F7:F46,E52,G7:G46)-SUMPRODUCT((F7:F46=E52)*(O7:O46<>"")*IFERROR(O7:O46/H7:H46,0)) -> 0
E53: TRY | F53: =SUMIF(F7:F46,E53,G7:G46)-SUMPRODUCT((F7:F46=E53)*(O7:O46<>"")*IFERROR(O7:O46/H7:H46,0)) -> 0

Sheet Bank Balances
A1: BANK & CASH BALANCES
A2: Opening liquidity as at the report date. Foreign currency balances convert to ₺ using the Dashboard FX rates.
A4: No | B4: Bank | C4: Account Name / IBAN (last 4) | D4: Account Type | E4: Currency | F4: Balance (FCY) | G4: FX Rate (to ₺) | H4: Balance (₺) | I4: Available for Operations? | J4: Notes
A5: =IF(B5="","",ROW()-4) -> 1 | B5: Garanti BBVA | C5: Operating account – ****4821 | D5: Current | E5: TRY | F5: 1250000 | G5: =IF(B5="","",IFERROR(INDEX(Dashboard!$G$9:$G$12,MATCH(E5,Dashboard!$F$9:$F$12,0)),1)) -> 1 | H5: =IF(B5="","",F5*G5) -> 1250000 | I5: Yes | J5: Sample row – replace with live data
A6: =IF(B6="","",ROW()-4) -> 2 | B6: İş Bankası | C6: FX account – ****1177 | D6: Current | E6: EUR | F6: 15000 | G6: =IF(B6="","",IFERROR(INDEX(Dashboard!$G$9:$G$12,MATCH(E6,Dashboard!$F$9:$F$12,0)),1)) -> 47.8 | H6: =IF(B6="","",F6*G6) -> 717000 | I6: Yes | J6: Sample row – replace with live data
A7: =IF(B7="","",ROW()-4) -> 3 | B7: Garanti BBVA | C7: Overnight deposit – ****4839 | D7: Deposit | E7: TRY | F7: 500000 | G7: =IF(B7="","",IFERROR(INDEX(Dashboard!$G$9:$G$12,MATCH(E7,Dashboard!$F$9:$F$12,0)),1)) -> 1 | H7: =IF(B7="","",F7*G7) -> 500000 | I7: No | J7: Sample row – replace with live data
A8: =IF(B8="","",ROW()-4) -> 4 | B8: Petty cash | C8: Office safe | D8: Cash | E8: TRY | F8: 8500 | G8: =IF(B8="","",IFERROR(INDEX(Dashboard!$G$9:$G$12,MATCH(E8,Dashboard!$F$9:$F$12,0)),1)) -> 1 | H8: =IF(B8="","",F8*G8) -> 8500 | I8: Yes | J8: Sample row – replace with live data
A9: =IF(B9="","",ROW()-4) | G9: =IF(B9="","",IFERROR(INDEX(Dashboard!$G$9:$G$12,MATCH(E9,Dashboard!$F$9:$F$12,0)),1)) | H9: =IF(B9="","",F9*G9)
A10: =IF(B10="","",ROW()-4) | G10: =IF(B10="","",IFERROR(INDEX(Dashboard!$G$9:$G$12,MATCH(E10,Dashboard!$F$9:$F$12,0)),1)) | H10: =IF(B10="","",F10*G10)
A11: =IF(B11="","",ROW()-4) | G11: =IF(B11="","",IFERROR(INDEX(Dashboard!$G$9:$G$12,MATCH(E11,Dashboard!$F$9:$F$12,0)),1)) | H11: =IF(B11="","",F11*G11)
A12: =IF(B12="","",ROW()-4) | G12: =IF(B12="","",IFERROR(INDEX(Dashboard!$G$9:$G$12,MATCH(E12,Dashboard!$F$9:$F$12,0)),1)) | H12: =IF(B12="","",F12*G12)
A13: =IF(B13="","",ROW()-4) | G13: =IF(B13="","",IFERROR(INDEX(Dashboard!$G$9:$G$12,MATCH(E13,Dashboard!$F$9:$F$12,0)),1)) | H13: =IF(B13="","",F13*G13)
A14: =IF(B14="","",ROW()-4) | G14: =IF(B14="","",IFERROR(INDEX(Dashboard!$G$9:$G$12,MATCH(E14,Dashboard!$F$9:$F$12,0)),1)) | H14: =IF(B14="","",F14*G14)
A15: =IF(B15="","",ROW()-4) | G15: =IF(B15="","",IFERROR(INDEX(Dashboard!$G$9:$G$12,MATCH(E15,Dashboard!$F$9:$F$12,0)),1)) | H15: =IF(B15="","",F15*G15)
A16: =IF(B16="","",ROW()-4) | G16: =IF(B16="","",IFERROR(INDEX(Dashboard!$G$9:$G$12,MATCH(E16,Dashboard!$F$9:$F$12,0)),1)) | H16: =IF(B16="","",F16*G16)
A17: =IF(B17="","",ROW()-4) | G17: =IF(B17="","",IFERROR(INDEX(Dashboard!$G$9:$G$12,MATCH(E17,Dashboard!$F$9:$F$12,0)),1)) | H17: =IF(B17="","",F17*G17)
A18: =IF(B18="","",ROW()-4) | G18: =IF(B18="","",IFERROR(INDEX(Dashboard!$G$9:$G$12,MATCH(E18,Dashboard!$F$9:$F$12,0)),1)) | H18: =IF(B18="","",F18*G18)
A19: =IF(B19="","",ROW()-4) | G19: =IF(B19="","",IFERROR(INDEX(Dashboard!$G$9:$G$12,MATCH(E19,Dashboard!$F$9:$F$12,0)),1)) | H19: =IF(B19="","",F19*G19)
A20: =IF(B20="","",ROW()-4) | G20: =IF(B20="","",IFERROR(INDEX(Dashboard!$G$9:$G$12,MATCH(E20,Dashboard!$F$9:$F$12,0)),1)) | H20: =IF(B20="","",F20*G20)
... A24: =IF(B24="","",ROW()-4) | G24: =IF(B24="","",IFERROR(INDEX(Dashboard!$G$9:$G$12,MATCH(E24,Dashboard!$F$9:$F$12,0)),1)) | H24: =IF(B24="","",F24*G24)
B25: TOTAL BANK & CASH | H25: =SUM(H5:H24) -> 2475500
B26: of which available for operations | H26: =SUMIF(I5:I24,"Yes",H5:H24) -> 1975500
B27: of which restricted / deposits | H27: =H25-H26 -> 500000
B29: Balances by currency (FCY) | C29: Amount (FCY) | D29: Equivalent (₺)
B30: TRY | C30: =SUMIF(E5:E24,B30,F5:F24) -> 1758500 | D30: =SUMIF(E5:E24,B30,H5:H24) -> 1758500
B31: GBP | C31: =SUMIF(E5:E24,B31,F5:F24) -> 0 | D31: =SUMIF(E5:E24,B31,H5:H24) -> 0
B32: EUR | C32: =SUMIF(E5:E24,B32,F5:F24) -> 15000 | D32: =SUMIF(E5:E24,B32,H5:H24) -> 717000
B33: USD | C33: =SUMIF(E5:E24,B33,F5:F24) -> 0 | D33: =SUMIF(E5:E24,B33,H5:H24) -> 0
